Workbook

Sheet Original
A1: Jogador | B1: total | C1: j01 | D1: j02 | E1: j03 | F1: j04 | G1: j05 | H1: j06 | I1: j07 | J1: j08 | K1: j09 | L1: j10 | M1: j11 | N1: j12 | O1: j13 | P1: j14 | Q1: j15 | R1: j16 | S1: j17 | T1: j18 | U1: j19 | V1: j20 | W1: j21 | X1: j22 | Y1: j23 | Z1: j24 | AA1: j25 | AB1: j26 | AC1: j27 | AD1: j28 | AE1: j29 | AF1: j30 | AG1: j31 | AH1: j32 | AI1: j33 | AJ1: j34 | AK1: j35 | AL1: j36 | AM1: j37 | AN1: j38 | AO1: j39 | AP1: j40 | AQ1: j41 | AR1: j42 | AS1: j43 | AT1: j44 | AU1: j45 | AV1: j46 | AW1: j47 | AX1: j48 | AY1: j49 | AZ1: j50 | BA1: j51 | BB1: j52 | BC1: j53 | BD1: j54 | BE1: j55 | BF1: j56 | BG1: j57 | BH1: j58 | BI1: j59 | BJ1: j60 | BK1: j61 | BL1: j62 | BM1: j63 | BN1: j64 | BO1: j65 | BP1: j66 | BQ1: j67 | BR1: j68 | BS1: j69 | BT1: j70 | BU1: j71 | BV1: j72 | BW1: j73
A2: Marina Carvalho | B2: =SUM(C2:BW2) -> 168 | C2: 8 | D2: 6 | E2: 6 | F2: 13 | G2: 0 | H2: 2 | I2: 6 | J2: 8 | K2: 2 | L2: 0 | M2: 6 | N2: 6 | O2: 6 | P2: 2 | Q2: 8 | R2: 13 | S2: 0 | T2: 0 | U2: 6 | V2: 13 | W2: 0 | X2: 13 | Y2: 13 | Z2: 8 | AA2: 13 | AB2: 2 | AC2: 0 | AD2: 6 | AE2: 2
A3: Marcos Rogerio Magalhaes | B3: =SUM(C3:BW3) -> 167 | C3: 8 | D3: 6 | E3: 8 | F3: 13 | G3: 0 | H3: 2 | I3: 6 | J3: 6 | K3: 2 | L3: 2 | M3: 8 | N3: 8 | O3: 13 | P3: 6 | Q3: 6 | R3: 13 | S3: 7 | T3: 0 | U3: 8 | V3: 6 | W3: 0 | X3: 2 | Y3: 8 | Z3: 13 | AA3: 8 | AB3: 0 | AC3: 0 | AD3: 2 | AE3: 6
A4: Cristina Paradella Mottin | B4: =SUM(C4:BW4) -> 166 | C4: 8 | D4: 6 | E4: 13 | F4: 13 | G4: 0 | H4: 2 | I4: 0 | J4: 6 | K4: 2 | L4: 0 | M4: 8 | N4: 8 | O4: 13 | P4: 2 | Q4: 6 | R4: 8 | S4: 7 | T4: 0 | U4: 6 | V4: 2 | W4: 2 | X4: 6 | Y4: 13 | Z4: 13 | AA4: 6 | AB4: 2 | AC4: 0 | AD4: 8 | AE4: 6
A5: Fábio Luis Dos Santo Aleluia | B5: =SUM(C5:BW5) -> 166 | C5: 13 | D5: 6 | E5: 8 | F5: 2 | G5: 0 | H5: 2 | I5: 2 | J5: 6 | K5: 2 | L5: 0 | M5: 8 | N5: 6 | O5: 13 | P5: 2 | Q5: 6 | R5: 13 | S5: 0 | T5: 0 | U5: 13 | V5: 0 | W5: 13 | X5: 8 | Y5: 8 | Z5: 6 | AA5: 8 | AB5: 13 | AC5: 0 | AD5: 6 | AE5: 2
A6: Gabriel Coni | B6: =SUM(C6:BW6) -> 163 | C6: 8 | D6: 6 | E6: 8 | F6: 13 | G6: 0 | H6: 2 | I6: 6 | J6: 8 | K6: 2 | L6: 0 | M6: 8 | N6: 8 | O6: 13 | P6: 6 | Q6: 6 | R6: 13 | S6: 7 | T6: 0 | U6: 0 | V6: 2 | W6: 2 | X6: 13 | Y6: 8 | Z6: 2 | AA6: 8 | AB6: 0 | AC6: 0 | AD6: 8 | AE6: 6
A7: Paulo Machado | B7: =SUM(C7:BW7) -> 163 | C7: 6 | D7: 6 | E7: 8 | F7: 13 | G7: 0 | H7: 2 | I7: 6 | J7: 8 | K7: 6 | L7: 0 | M7: 0 | N7: 8 | O7: 2 | P7: 13 | Q7: 6 | R7: 8 | S7: 0 | T7: 2 | U7: 2 | V7: 13 | W7: 2 | X7: 13 | Y7: 8 | Z7: 6 | AA7: 13 | AB7: 0 | AC7: 0 | AD7: 6 | AE7: 6
A8: Ivã das Neves Reis | B8: =SUM(C8:BW8) -> 161 | C8: 8 | D8: 6 | E8: 13 | F8: 13 | G8: 0 | H8: 2 | I8: 6 | J8: 8 | K8: 2 | L8: 2 | M8: 6 | N8: 6 | O8: 0 | P8: 2 | Q8: 6 | R8: 8 | S8: 0 | T8: 8 | U8: 13 | V8: 2 | W8: 0 | X8: 13 | Y8: 8 | Z8: 13 | AA8: 2 | AB8: 2 | AC8: 0 | AD8: 6 | AE8: 6
A9: Rafael Vieira Valente | B9: =SUM(C9:BW9) -> 159 | C9: 8 | D9: 6 | E9: 8 | F9: 13 | G9: 0 | H9: 0 | I9: 6 | J9: 6 | K9: 2 | L9: 0 | M9: 8 | N9: 13 | O9: 13 | P9: 2 | Q9: 0 | R9: 6 | S9: 0 | T9: 8 | U9: 6 | V9: 2 | W9: 2 | X9: 2 | Y9: 13 | Z9: 0 | AA9: 8 | AB9: 13 | AC9: 0 | AD9: 8 | AE9: 6
A10: Brunner Victor de Almeida | B10: =SUM(C10:BW10) -> 158 | C10: 8 | D10: 6 | E10: 13 | F10: 13 | G10: 0 | H10: 2 | I10: 6 | J10: 6 | K10: 2 | L10: 0 | M10: 8 | N10: 13 | O10: 6 | P10: 2 | Q10: 6 | R10: 8 | S10: 7 | T10: 0 | U10: 8 | V10: 2 | W10: 0 | X10: 2 | Y10: 13 | Z10: 13 | AA10: 8 | AB10: 2 | AC10: 0 | AD10: 2 | AE10: 2
A11: Risia Gouveia | B11: =SUM(C11:BW11) -> 155 | C11: 0 | D11: 6 | E11: 13 | F11: 13 | G11: 0 | H11: 2 | I11: 0 | J11: 6 | K11: 2 | L11: 0 | M11: 6 | N11: 6 | O11: 6 | P11: 2 | Q11: 6 | R11: 13 | S11: 0 | T11: 0 | U11: 8 | V11: 2 | W11: 2 | X11: 13 | Y11: 13 | Z11: 13 | AA11: 13 | AB11: 2 | AC11: 0 | AD11: 6 | AE11: 2
A12: Simara Magalhães | B12: =SUM(C12:BW12) -> 155 | C12: 2 | D12: 6 | E12: 8 | F12: 2 | G12: 0 | H12: 2 | I12: 6 | J12: 8 | K12: 0 | L12: 0 | M12: 6 | N12: 8 | O12: 6 | P12: 2 | Q12: 6 | R12: 13 | S12: 7 | T12: 0 | U12: 6 | V12: 2 | W12: 6 | X12: 13 | Y12: 8 | Z12: 13 | AA12: 13 | AB12: 2 | AC12: 0 | AD12: 8 | AE12: 2
A13: Luciano Santana Barros 1 | B13: =SUM(C13:BW13) -> 154 | C13: 13 | D13: 6 | E13: 8 | F13: 0 | G13: 0 | H13: 2 | I13: 0 | J13: 8 | K13: 13 | L13: 2 | M13: 8 | N13: 13 | O13: 6 | P13: 2 | Q13: 6 | R13: 8 | S13: 0 | T13: 2 | U13: 8 | V13: 0 | W13: 0 | X13: 8 | Y13: 8 | Z13: 13 | AA13: 8 | AB13: 2 | AC13: 0 | AD13: 8 | AE13: 2
... A115: Tatsuhiko Kawaoka | B115: =SUM(C115:BW115) -> 77 | C115: 0 | D115: 6 | E115: 0 | F115: 2 | G115: 0 | H115: 6 | I115: 0 | J115: 6 | K115: 2 | L115: 2 | M115: 8 | N115: 8 | O115: 6 | P115: 2 | Q115: 0 | R115: 0 | S115: 7 | T115: 0 | U115: 2 | V115: 0 | W115: 0 | X115: 0 | Y115: 8 | Z115: 2 | AA115: 0 | AB115: 0 | AC115: 0 | AD115: 8 | AE115: 2

Sheet Acumulado
A1: Jogador | B1: total | C1: j01 | D1: j02 | E1: j03 | F1: j04 | G1: j05 | H1: j06 | I1: j07 | J1: j08 | K1: j09 | L1: j10 | M1: j11 | N1: j12 | O1: j13 | P1: j14 | Q1: j15 | R1: j16 | S1: j17 | T1: j18 | U1: j19 | V1: j20 | W1: j21 | X1: j22 | Y1: j23 | Z1: j24 | AA1: j25 | AB1: j26 | AC1: j27 | AD1: j28 | AE1: j29 | AF1: j30 | AG1: j31 | AH1: j32 | AI1: j33 | AJ1: j34 | AK1: j35 | AL1: j36 | AM1: j37 | AN1: j38 | AO1: j39 | AP1: j40 | AQ1: j41 | AR1: j42 | AS1: j43 | AT1: j44 | AU1: j45 | AV1: j46 | AW1: j47 | AX1: j48 | AY1: j49 | AZ1: j50 | BA1: j51 | BB1: j52 | BC1: j53 | BD1: j54 | BE1: j55 | BF1: j56 | BG1: j57 | BH1: j58 | BI1: j59 | BJ1: j60 | BK1: j61 | BL1: j62 | BM1: j63 | BN1: j64 | BO1: j65 | BP1: j66 | BQ1: j67 | BR1: j68 | BS1: j69 | BT1: j70 | BU1: j71 | BV1: j72 | BW1: j73
A2: =Original!A2 -> Marina Carvalho | B2: =Original!B2 -> 168 | C2: =Original!C2 -> 8 | D2: =C2+Original!D2 -> 14 | E2: =D2+Original!E2 -> 20 | F2: =E2+Original!F2 -> 33 | G2: =F2+Original!G2 -> 33 | H2: =G2+Original!H2 -> 35 | I2: =H2+Original!I2 -> 41 | J2: =I2+Original!J2 -> 49 | K2: =J2+Original!K2 -> 51 | ... BW2: =BV2+Original!BW2 -> 168
A3: =Original!A3 -> Marcos Rogerio Magalhaes | B3: =Original!B3 -> 167 | C3: =Original!C3 -> 8 | D3: =C3+Original!D3 -> 14 | E3: =D3+Original!E3 -> 22 | F3: =E3+Original!F3 -> 35 | G3: =F3+Original!G3 -> 35 | H3: =G3+Original!H3 -> 37 | I3: =H3+Original!I3 -> 43 | J3: =I3+Original!J3 -> 49 | K3: =J3+Original!K3 -> 51 | ... BW3: =BV3+Original!BW3 -> 167
A4: =Original!A4 -> Cristina Paradella Mottin | B4: =Original!B4 -> 166 | C4: =Original!C4 -> 8 | D4: =C4+Original!D4 -> 14 | E4: =D4+Original!E4 -> 27 | F4: =E4+Original!F4 -> 40 | G4: =F4+Original!G4 -> 40 | H4: =G4+Original!H4 -> 42 | I4: =H4+Original!I4 -> 42 | J4: =I4+Original!J4 -> 48 | K4: =J4+Original!K4 -> 50 | ... BW4: =BV4+Original!BW4 -> 166
A5: =Original!A5 -> Fábio Luis Dos Santo Aleluia | B5: =Original!B5 -> 166 | C5: =Original!C5 -> 13 | D5: =C5+Original!D5 -> 19 | E5: =D5+Original!E5 -> 27 | F5: =E5+Original!F5 -> 29 | G5: =F5+Original!G5 -> 29 | H5: =G5+Original!H5 -> 31 | I5: =H5+Original!I5 -> 33 | J5: =I5+Original!J5 -> 39 | K5: =J5+Original!K5 -> 41 | ... BW5: =BV5+Original!BW5 -> 166
A6: =Original!A6 -> Gabriel Coni | B6: =Original!B6 -> 163 | C6: =Original!C6 -> 8 | D6: =C6+Original!D6 -> 14 | E6: =D6+Original!E6 -> 22 | F6: =E6+Original!F6 -> 35 | G6: =F6+Original!G6 -> 35 | H6: =G6+Original!H6 -> 37 | I6: =H6+Original!I6 -> 43 | J6: =I6+Original!J6 -> 51 | K6: =J6+Original!K6 -> 53 | ... BW6: =BV6+Original!BW6 -> 163
A7: =Original!A7 -> Paulo Machado | B7: =Original!B7 -> 163 | C7: =Original!C7 -> 6 | D7: =C7+Original!D7 -> 12 | E7: =D7+Original!E7 -> 20 | F7: =E7+Original!F7 -> 33 | G7: =F7+Original!G7 -> 33 | H7: =G7+Original!H7 -> 35 | I7: =H7+Original!I7 -> 41 | J7: =I7+Original!J7 -> 49 | K7: =J7+Original!K7 -> 55 | ... BW7: =BV7+Original!BW7 -> 163
A8: =Original!A8 -> Ivã das Neves Reis | B8: =Original!B8 -> 161 | C8: =Original!C8 -> 8 | D8: =C8+Original!D8 -> 14 | E8: =D8+Original!E8 -> 27 | F8: =E8+Original!F8 -> 40 | G8: =F8+Original!G8 -> 40 | H8: =G8+Original!H8 -> 42 | I8: =H8+Original!I8 -> 48 | J8: =I8+Original!J8 -> 56 | K8: =J8+Original!K8 -> 58 | ... BW8: =BV8+Original!BW8 -> 161
A9: =Original!A9 -> Rafael Vieira Valente | B9: =Original!B9 -> 159 | C9: =Original!C9 -> 8 | D9: =C9+Original!D9 -> 14 | E9: =D9+Original!E9 -> 22 | F9: =E9+Original!F9 -> 35 | G9: =F9+Original!G9 -> 35 | H9: =G9+Original!H9 -> 35 | I9: =H9+Original!I9 -> 41 | J9: =I9+Original!J9 -> 47 | K9: =J9+Original!K9 -> 49 | ... BW9: =BV9+Original!BW9 -> 159
A10: =Original!A10 -> Brunner Victor de Almeida | B10: =Original!B10 -> 158 | C10: =Original!C10 -> 8 | D10: =C10+Original!D10 -> 14 | E10: =D10+Original!E10 -> 27 | F10: =E10+Original!F10 -> 40 | G10: =F10+Original!G10 -> 40 | H10: =G10+Original!H10 -> 42 | I10: =H10+Original!I10 -> 48 | J10: =I10+Original!J10 -> 54 | K10: =J10+Original!K10 -> 56 | ... BW10: =BV10+Original!BW10 -> 158
A11: =Original!A11 -> Risia Gouveia | B11: =Original!B11 -> 155 | C11: =Original!C11 -> 0 | D11: =C11+Original!D11 -> 6 | E11: =D11+Original!E11 -> 19 | F11: =E11+Original!F11 -> 32 | G11: =F11+Original!G11 -> 32 | H11: =G11+Original!H11 -> 34 | I11: =H11+Original!I11 -> 34 | J11: =I11+Original!J11 -> 40 | K11: =J11+Original!K11 -> 42 | ... BW11: =BV11+Original!BW11 -> 155
A12: =Original!A12 -> Simara Magalhães | B12: =Original!B12 -> 155 | C12: =Original!C12 -> 2 | D12: =C12+Original!D12 -> 8 | E12: =D12+Original!E12 -> 16 | F12: =E12+Original!F12 -> 18 | G12: =F12+Original!G12 -> 18 | H12: =G12+Original!H12 -> 20 | I12: =H12+Original!I12 -> 26 | J12: =I12+Original!J12 -> 34 | K12: =J12+Original!K12 -> 34 | ... BW12: =BV12+Original!BW12 -> 155
A13: =Original!A13 -> Luciano Santana Barros 1 | B13: =Original!B13 -> 154 | C13: =Original!C13 -> 13 | D13: =C13+Original!D13 -> 19 | E13: =D13+Original!E13 -> 27 | F13: =E13+Original!F13 -> 27 | G13: =F13+Original!G13 -> 27 | H13: =G13+Original!H13 -> 29 | I13: =H13+Original!I13 -> 29 | J13: =I13+Original!J13 -> 37 | K13: =J13+Original!K13 -> 50 | ... BW13: =BV13+Original!BW13 -> 154
... A115: =Original!A115 -> Tatsuhiko Kawaoka | B115: =Original!B115 -> 77 | C115: =Original!C115 -> 0 | D115: =C115+Original!D115 -> 6 | E115: =D115+Original!E115 -> 6 | F115: =E115+Original!F115 -> 8 | G115: =F115+Original!G115 -> 8 | H115: =G115+Original!H115 -> 14 | I115: =H115+Original!I115 -> 14 | J115: =I115+Original!J115 -> 20 | K115: =J115+Original!K115 -> 22 | ... BW115: =BV115+Original!BW115 -> 77

Sheet Ranking
A1: Jogador | B1: total | C1: j01 | D1: j02 | E1: j03 | F1: j04 | G1: j05 | H1: j06 | I1: j07 | J1: j08 | K1: j09 | L1: j10 | M1: j11 | N1: j12 | O1: j13 | P1: j14 | Q1: j15 | R1: j16 | S1: j17 | T1: j18 | U1: j19 | V1: j20 | W1: j21 | X1: j22 | Y1: j23 | Z1: j24 | AA1: j25 | AB1: j26 | AC1: j27 | AD1: j28 | AE1: j29 | AF1: j30 | AG1: j31 | AH1: j32 | AI1: j33 | AJ1: j34 | AK1: j35 | AL1: j36 | AM1: j37 | AN1: j38 | AO1: j39 | AP1: j40 | AQ1: j41 | AR1: j42 | AS1: j43 | AT1: j44 | AU1: j45 | AV1: j46 | AW1: j47 | AX1: j48 | AY1: j49 | AZ1: j50 | BA1: j51 | BB1: j52 | BC1: j53 | BD1: j54 | BE1: j55 | BF1: j56 | BG1: j57 | BH1: j58 | BI1: j59 | BJ1: j60 | BK1: j61 | BL1: j62 | BM1: j63 | BN1: j64 | BO1: j65 | BP1: j66 | BQ1: j67 | BR1: j68 | BS1: j69 | BT1: j70 | BU1: j71 | BV1: j72 | BW1: j73
A2: =TAcum[[#This Row],[Jogador]] -> Marina Carvalho | B2: =RANK(TAcum[[#This Row],[total]],TAcum[[#All],[total]],0) -> 1 | C2: =RANK(TAcum[[#This Row],[j01]],TAcum[[#All],[j01]],0) -> 13 | D2: =RANK(TAcum[[#This Row],[j02]],TAcum[[#All],[j02]],0) -> 14 | E2: =RANK(TAcum[[#This Row],[j03]],TAcum[[#All],[j03]],0) -> 52 | F2: =RANK(TAcum[[#This Row],[j04]],TAcum[[#All],[j04]],0) -> 27 | G2: =RANK(TAcum[[#This Row],[j05]],TAcum[[#All],[j05]],0) -> 27 | H2: =RANK(TAcum[[#This Row],[j06]],TAcum[[#All],[j06]],0) -> 23 | I2: =RANK(TAcum[[#This Row],[j07]],TAcum[[#All],[j07]],0) -> 16 | J2: =RANK(TAcum[[#This Row],[j08]],TAcum[[#All],[j08]],0) -> 8 | K2: =RANK(TAcum[[#This Row],[j09]],TAcum[[#All],[j09]],0) -> 11 | L2: =RANK(TAcum[[#This Row],[j10]],TAcum[[#All],[j10]],0) -> 15 | M2: =RANK(TAcum[[#This Row],[j11]],TAcum[[#All],[j11]],0) -> 17 | N2: =RANK(TAcum[[#This Row],[j12]],TAcum[[#All],[j12]],0) -> 22 | O2: =RANK(TAcum[[#This Row],[j13]],TAcum[[#All],[j13]],0) -> 30 | P2: =RANK(TAcum[[#This Row],[j14]],TAcum[[#All],[j14]],0) -> 32 | Q2: =RANK(TAcum[[#This Row],[j15]],TAcum[[#All],[j15]],0) -> 29 | R2: =RANK(TAcum[[#This Row],[j16]],TAcum[[#All],[j16]],0) -> 19 | S2: =RANK(TAcum[[#This Row],[j17]],TAcum[[#All],[j17]],0) -> 23 | T2: =RANK(TAcum[[#This Row],[j18]],TAcum[[#All],[j18]],0) -> 29 | U2: =RANK(TAcum[[#This Row],[j19]],TAcum[[#All],[j19]],0) -> 31 | V2: =RANK(TAcum[[#This Row],[j20]],TAcum[[#All],[j20]],0) -> 7 | W2: =RANK(TAcum[[#This Row],[j21]],TAcum[[#All],[j21]],0) -> 10 | X2: =RANK(TAcum[[#This Row],[j22]],TAcum[[#All],[j22]],0) -> 3 | Y2: =RANK(TAcum[[#This Row],[j23]],TAcum[[#All],[j23]],0) -> 3 | Z2: =RANK(TAcum[[#This Row],[j24]],TAcum[[#All],[j24]],0) -> 2 | AA2: =RANK(TAcum[[#This Row],[j25]],TAcum[[#All],[j25]],0) -> 2 | AB2: =RANK(TAcum[[#This Row],[j26]],TAcum[[#All],[j26]],0) -> 1 | AC2: =RANK(TAcum[[#This Row],[j27]],TAcum[[#All],[j27]],0) -> 1 | AD2: =RANK(TAcum[[#This Row],[j28]],TAcum[[#All],[j28]],0) -> 1 | AE2: =RANK(TAcum[[#This Row],[j29]],TAcum[[#All],[j29]],0) -> 1 | AF2: =RANK(TAcum[[#This Row],[j30]],TAcum[[#All],[j30]],0) -> 1 | AG2: =RANK(TAcum[[#This Row],[j31]],TAcum[[#All],[j31]],0) -> 1 | AH2: =RANK(TAcum[[#This Row],[j32]],TAcum[[#All],[j32]],0) -> 1 | AI2: =RANK(TAcum[[#This Row],[j33]],TAcum[[#All],[j33]],0) -> 1 | AJ2: =RANK(TAcum[[#This Row],[j34]],TAcum[[#All],[j34]],0) -> 1 | AK2: =RANK(TAcum[[#This Row],[j35]],TAcum[[#All],[j35]],0) -> 1 | AL2: =RANK(TAcum[[#This Row],[j36]],TAcum[[#All],[j36]],0) -> 1 | AM2: =RANK(TAcum[[#This Row],[j37]],TAcum[[#All],[j37]],0) -> 1 | AN2: =RANK(TAcum[[#This Row],[j38]],TAcum[[#All],[j38]],0) -> 1 | AO2: =RANK(TAcum[[#This Row],[j39]],TAcum[[#All],[j39]],0) -> 1 | AP2: =RANK(TAcum[[#This Row],[j40]],TAcum[[#All],[j40]],0) -> 1 | AQ2: =RANK(TAcum[[#This Row],[j41]],TAcum[[#All],[j41]],0) -> 1 | AR2: =RANK(TAcum[[#This Row],[j42]],TAcum[[#All],[j42]],0) -> 1 | AS2: =RANK(TAcum[[#This Row],[j43]],TAcum[[#All],[j43]],0) -> 1 | AT2: =RANK(TAcum[[#This Row],[j44]],TAcum[[#All],[j44]],0) -> 1 | AU2: =RANK(TAcum[[#This Row],[j45]],TAcum[[#All],[j45]],0) -> 1 | AV2: =RANK(TAcum[[#This Row],[j46]],TAcum[[#All],[j46]],0) -> 1 | AW2: =RANK(TAcum[[#This Row],[j47]],TAcum[[#All],[j47]],0) -> 1 | AX2: =RANK(TAcum[[#This Row],[j48]],TAcum[[#All],[j48]],0) -> 1 | AY2: =RANK(TAcum[[#This Row],[j49]],TAcum[[#All],[j49]],0) -> 1 | AZ2: =RANK(TAcum[[#This Row],[j50]],TAcum[[#All],[j50]],0) -> 1 | BA2: =RANK(TAcum[[#This Row],[j51]],TAcum[[#All],[j51]],0) -> 1 | BB2: =RANK(TAcum[[#This Row],[j52]],TAcum[[#All],[j52]],0) -> 1 | BC2: =RANK(TAcum[[#This Row],[j53]],TAcum[[#All],[j53]],0) -> 1 | BD2: =RANK(TAcum[[#This Row],[j54]],TAcum[[#All],[j54]],0) -> 1 | BE2: =RANK(TAcum[[#This Row],[j55]],TAcum[[#All],[j55]],0) -> 1 | BF2: =RANK(TAcum[[#This Row],[j56]],TAcum[[#All],[j56]],0) -> 1 | BG2: =RANK(TAcum[[#This Row],[j57]],TAcum[[#All],[j57]],0) -> 1 | BH2: =RANK(TAcum[[#This Row],[j58]],TAcum[[#All],[j58]],0) -> 1 | BI2: =RANK(TAcum[[#This Row],[j59]],TAcum[[#All],[j59]],0) -> 1 | BJ2: =RANK(TAcum[[#This Row],[j60]],TAcum[[#All],[j60]],0) -> 1 | BK2: =RANK(TAcum[[#This Row],[j61]],TAcum[[#All],[j61]],0) -> 1 | BL2: =RANK(TAcum[[#This Row],[j62]],TAcum[[#All],[j62]],0) -> 1 | BM2: =RANK(TAcum[[#This Row],[j63]],TAcum[[#All],[j63]],0) -> 1 | BN2: =RANK(TAcum[[#This Row],[j64]],TAcum[[#All],[j64]],0) -> 1 | BO2: =RANK(TAcum[[#This Row],[j65]],TAcum[[#All],[j65]],0) -> 1 | BP2: =RANK(TAcum[[#This Row],[j66]],TAcum[[#All],[j66]],0) -> 1 | BQ2: =RANK(TAcum[[#This Row],[j67]],TAcum[[#All],[j67]],0) -> 1 | BR2: =RANK(TAcum[[#This Row],[j68]],TAcum[[#All],[j68]],0) -> 1 | BS2: =RANK(TAcum[[#This Row],[j69]],TAcum[[#All],[j69]],0) -> 1 | BT2: =RANK(TAcum[[#This Row],[j70]],TAcum[[#All],[j70]],0) -> 1 | BU2: =RANK(TAcum[[#This Row],[j71]],TAcum[[#All],[j71]],0) -> 1 | BV2: =RANK(TAcum[[#This Row],[j72]],TAcum[[#All],[j72]],0) -> 1 | BW2: =RANK(TAcum[[#This Row],[j73]],TAcum[[#All],[j73]],0) -> 1
A3: =TAcum[[#This Row],[Jogador]] -> Marcos Rogerio Magalhaes | B3: =RANK(TAcum[[#This Row],[total]],TAcum[[#All],[total]],0) -> 2 | C3: =RANK(TAcum[[#This Row],[j01]],TAcum[[#All],[j01]],0) -> 13 | D3: =RANK(TAcum[[#This Row],[j02]],TAcum[[#All],[j02]],0) -> 14 | E3: =RANK(TAcum[[#This Row],[j03]],TAcum[[#All],[j03]],0) -> 24 | F3: =RANK(TAcum[[#This Row],[j04]],TAcum[[#All],[j04]],0) -> 9 | G3: =RANK(TAcum[[#This Row],[j05]],TAcum[[#All],[j05]],0) -> 9 | H3: =RANK(TAcum[[#This Row],[j06]],TAcum[[#All],[j06]],0) -> 9 | I3: =RANK(TAcum[[#This Row],[j07]],TAcum[[#All],[j07]],0) -> 5 | J3: =RANK(TAcum[[#This Row],[j08]],TAcum[[#All],[j08]],0) -> 8 | K3: =RANK(TAcum[[#This Row],[j09]],TAcum[[#All],[j09]],0) -> 11 | L3: =RANK(TAcum[[#This Row],[j10]],TAcum[[#All],[j10]],0) -> 7 | M3: =RANK(TAcum[[#This Row],[j11]],TAcum[[#All],[j11]],0) -> 6 | N3: =RANK(TAcum[[#This Row],[j12]],TAcum[[#All],[j12]],0) -> 9 | O3: =RANK(TAcum[[#This Row],[j13]],TAcum[[#All],[j13]],0) -> 5 | P3: =RANK(TAcum[[#This Row],[j14]],TAcum[[#All],[j14]],0) -> 1 | Q3: =RANK(TAcum[[#This Row],[j15]],TAcum[[#All],[j15]],0) -> 1 | R3: =RANK(TAcum[[#This Row],[j16]],TAcum[[#All],[j16]],0) -> 1 | S3: =RANK(TAcum[[#This Row],[j17]],TAcum[[#All],[j17]],0) -> 1 | T3: =RANK(TAcum[[#This Row],[j18]],TAcum[[#All],[j18]],0) -> 1 | U3: =RANK(TAcum[[#This Row],[j19]],TAcum[[#All],[j19]],0) -> 1 | V3: =RANK(TAcum[[#This Row],[j20]],TAcum[[#All],[j20]],0) -> 1 | W3: =RANK(TAcum[[#This Row],[j21]],TAcum[[#All],[j21]],0) -> 1 | X3: =RANK(TAcum[[#This Row],[j22]],TAcum[[#All],[j22]],0) -> 2 | Y3: =RANK(TAcum[[#This Row],[j23]],TAcum[[#All],[j23]],0) -> 2 | Z3: =RANK(TAcum[[#This Row],[j24]],TAcum[[#All],[j24]],0) -> 1 | AA3: =RANK(TAcum[[#This Row],[j25]],TAcum[[#All],[j25]],0) -> 1 | AB3: =RANK(TAcum[[#This Row],[j26]],TAcum[[#All],[j26]],0) -> 2 | AC3: =RANK(TAcum[[#This Row],[j27]],TAcum[[#All],[j27]],0) -> 2 | AD3: =RANK(TAcum[[#This Row],[j28]],TAcum[[#All],[j28]],0) -> 3 | AE3: =RANK(TAcum[[#This Row],[j29]],TAcum[[#All],[j29]],0) -> 2 | AF3: =RANK(TAcum[[#This Row],[j30]],TAcum[[#All],[j30]],0) -> 2 | AG3: =RANK(TAcum[[#This Row],[j31]],TAcum[[#All],[j31]],0) -> 2 | AH3: =RANK(TAcum[[#This Row],[j32]],TAcum[[#All],[j32]],0) -> 2 | AI3: =RANK(TAcum[[#This Row],[j33]],TAcum[[#All],[j33]],0) -> 2 | AJ3: =RANK(TAcum[[#This Row],[j34]],TAcum[[#All],[j34]],0) -> 2 | AK3: =RANK(TAcum[[#This Row],[j35]],TAcum[[#All],[j35]],0) -> 2 | AL3: =RANK(TAcum[[#This Row],[j36]],TAcum[[#All],[j36]],0) -> 2 | AM3: =RANK(TAcum[[#This Row],[j37]],TAcum[[#All],[j37]],0) -> 2 | AN3: =RANK(TAcum[[#This Row],[j38]],TAcum[[#All],[j38]],0) -> 2 | AO3: =RANK(TAcum[[#This Row],[j39]],TAcum[[#All],[j39]],0) -> 2 | AP3: =RANK(TAcum[[#This Row],[j40]],TAcum[[#All],[j40]],0) -> 2 | AQ3: =RANK(TAcum[[#This Row],[j41]],TAcum[[#All],[j41]],0) -> 2 | AR3: =RANK(TAcum[[#This Row],[j42]],TAcum[[#All],[j42]],0) -> 2 | AS3: =RANK(TAcum[[#This Row],[j43]],TAcum[[#All],[j43]],0) -> 2 | AT3: =RANK(TAcum[[#This Row],[j44]],TAcum[[#All],[j44]],0) -> 2 | AU3: =RANK(TAcum[[#This Row],[j45]],TAcum[[#All],[j45]],0) -> 2 | AV3: =RANK(TAcum[[#This Row],[j46]],TAcum[[#All],[j46]],0) -> 2 | AW3: =RANK(TAcum[[#This Row],[j47]],TAcum[[#All],[j47]],0) -> 2 | AX3: =RANK(TAcum[[#This Row],[j48]],TAcum[[#All],[j48]],0) -> 2 | AY3: =RANK(TAcum[[#This Row],[j49]],TAcum[[#All],[j49]],0) -> 2 | AZ3: =RANK(TAcum[[#This Row],[j50]],TAcum[[#All],[j50]],0) -> 2 | BA3: =RANK(TAcum[[#This Row],[j51]],TAcum[[#All],[j51]],0) -> 2 | BB3: =RANK(TAcum[[#This Row],[j52]],TAcum[[#All],[j52]],0) -> 2 | BC3: =RANK(TAcum[[#This Row],[j53]],TAcum[[#All],[j53]],0) -> 2 | BD3: =RANK(TAcum[[#This Row],[j54]],TAcum[[#All],[j54]],0) -> 2 | BE3: =RANK(TAcum[[#This Row],[j55]],TAcum[[#All],[j55]],0) -> 2 | BF3: =RANK(TAcum[[#This Row],[j56]],TAcum[[#All],[j56]],0) -> 2 | BG3: =RANK(TAcum[[#This Row],[j57]],TAcum[[#All],[j57]],0) -> 2 | BH3: =RANK(TAcum[[#This Row],[j58]],TAcum[[#All],[j58]],0) -> 2 | BI3: =RANK(TAcum[[#This Row],[j59]],TAcum[[#All],[j59]],0) -> 2 | BJ3: =RANK(TAcum[[#This Row],[j60]],TAcum[[#All],[j60]],0) -> 2 | BK3: =RANK(TAcum[[#This Row],[j61]],TAcum[[#All],[j61]],0) -> 2 | BL3: =RANK(TAcum[[#This Row],[j62]],TAcum[[#All],[j62]],0) -> 2 | BM3: =RANK(TAcum[[#This Row],[j63]],TAcum[[#All],[j63]],0) -> 2 | BN3: =RANK(TAcum[[#This Row],[j64]],TAcum[[#All],[j64]],0) -> 2 | BO3: =RANK(TAcum[[#This Row],[j65]],TAcum[[#All],[j65]],0) -> 2 | BP3: =RANK(TAcum[[#This Row],[j66]],TAcum[[#All],[j66]],0) -> 2 | BQ3: =RANK(TAcum[[#This Row],[j67]],TAcum[[#All],[j67]],0) -> 2 | BR3: =RANK(TAcum[[#This Row],[j68]],TAcum[[#All],[j68]],0) -> 2 | BS3: =RANK(TAcum[[#This Row],[j69]],TAcum[[#All],[j69]],0) -> 2 | BT3: =RANK(TAcum[[#This Row],[j70]],TAcum[[#All],[j70]],0) -> 2 | BU3: =RANK(TAcum[[#This Row],[j71]],TAcum[[#All],[j71]],0) -> 2 | BV3: =RANK(TAcum[[#This Row],[j72]],TAcum[[#All],[j72]],0) -> 2 | BW3: =RANK(TAcum[[#This Row],[j73]],TAcum[[#All],[j73]],0) -> 2
A4: =TAcum[[#This Row],[Jogador]] -> Cristina Paradella Mottin | B4: =RANK(TAcum[[#This Row],[total]],TAcum[[#All],[total]],0) -> 3 | C4: =RANK(TAcum[[#This Row],[j01]],TAcum[[#All],[j01]],0) -> 13 | D4: =RANK(TAcum[[#This Row],[j02]],TAcum[[#All],[j02]],0) -> 14 | E4: =RANK(TAcum[[#This Row],[j03]],TAcum[[#All],[j03]],0) -> 3 | F4: =RANK(TAcum[[#This Row],[j04]],TAcum[[#All],[j04]],0) -> 1 | G4: =RANK(TAcum[[#This Row],[j05]],TAcum[[#All],[j05]],0) -> 1 | H4: =RANK(TAcum[[#This Row],[j06]],TAcum[[#All],[j06]],0) -> 1 | I4: =RANK(TAcum[[#This Row],[j07]],TAcum[[#All],[j07]],0) -> 11 | J4: =RANK(TAcum[[#This Row],[j08]],TAcum[[#All],[j08]],0) -> 15 | K4: =RANK(TAcum[[#This Row],[j09]],TAcum[[#All],[j09]],0) -> 16 | L4: =RANK(TAcum[[#This Row],[j10]],TAcum[[#All],[j10]],0) -> 19 | M4: =RANK(TAcum[[#This Row],[j11]],TAcum[[#All],[j11]],0) -> 16 | N4: =RANK(TAcum[[#This Row],[j12]],TAcum[[#All],[j12]],0) -> 15 | O4: =RANK(TAcum[[#This Row],[j13]],TAcum[[#All],[j13]],0) -> 10 | P4: =RANK(TAcum[[#This Row],[j14]],TAcum[[#All],[j14]],0) -> 10 | Q4: =RANK(TAcum[[#This Row],[j15]],TAcum[[#All],[j15]],0) -> 9 | R4: =RANK(TAcum[[#This Row],[j16]],TAcum[[#All],[j16]],0) -> 10 | S4: =RANK(TAcum[[#This Row],[j17]],TAcum[[#All],[j17]],0) -> 6 | T4: =RANK(TAcum[[#This Row],[j18]],TAcum[[#All],[j18]],0) -> 7 | U4: =RANK(TAcum[[#This Row],[j19]],TAcum[[#All],[j19]],0) -> 8 | V4: =RANK(TAcum[[#This Row],[j20]],TAcum[[#All],[j20]],0) -> 10 | W4: =RANK(TAcum[[#This Row],[j21]],TAcum[[#All],[j21]],0) -> 7 | X4: =RANK(TAcum[[#This Row],[j22]],TAcum[[#All],[j22]],0) -> 9 | Y4: =RANK(TAcum[[#This Row],[j23]],TAcum[[#All],[j23]],0) -> 6 | Z4: =RANK(TAcum[[#This Row],[j24]],TAcum[[#All],[j24]],0) -> 4 | AA4: =RANK(TAcum[[#This Row],[j25]],TAcum[[#All],[j25]],0) -> 5 | AB4: =RANK(TAcum[[#This Row],[j26]],TAcum[[#All],[j26]],0) -> 5 | AC4: =RANK(TAcum[[#This Row],[j27]],TAcum[[#All],[j27]],0) -> 5 | AD4: =RANK(TAcum[[#This Row],[j28]],TAcum[[#All],[j28]],0) -> 4 | AE4: =RANK(TAcum[[#This Row],[j29]],TAcum[[#All],[j29]],0) -> 3 | AF4: =RANK(TAcum[[#This Row],[j30]],TAcum[[#All],[j30]],0) -> 3 | AG4: =RANK(TAcum[[#This Row],[j31]],TAcum[[#All],[j31]],0) -> 3 | AH4: =RANK(TAcum[[#This Row],[j32]],TAcum[[#All],[j32]],0) -> 3 | AI4: =RANK(TAcum[[#This Row],[j33]],TAcum[[#All],[j33]],0) -> 3 | AJ4: =RANK(TAcum[[#This Row],[j34]],TAcum[[#All],[j34]],0) -> 3 | AK4: =RANK(TAcum[[#This Row],[j35]],TAcum[[#All],[j35]],0) -> 3 | AL4: =RANK(TAcum[[#This Row],[j36]],TAcum[[#All],[j36]],0) -> 3 | AM4: =RANK(TAcum[[#This Row],[j37]],TAcum[[#All],[j37]],0) -> 3 | AN4: =RANK(TAcum[[#This Row],[j38]],TAcum[[#All],[j38]],0) -> 3 | AO4: =RANK(TAcum[[#This Row],[j39]],TAcum[[#All],[j39]],0) -> 3 | AP4: =RANK(TAcum[[#This Row],[j40]],TAcum[[#All],[j40]],0) -> 3 | AQ4: =RANK(TAcum[[#This Row],[j41]],TAcum[[#All],[j41]],0) -> 3 | AR4: =RANK(TAcum[[#This Row],[j42]],TAcum[[#All],[j42]],0) -> 3 | AS4: =RANK(TAcum[[#This Row],[j43]],TAcum[[#All],[j43]],0) -> 3 | AT4: =RANK(TAcum[[#This Row],[j44]],TAcum[[#All],[j44]],0) -> 3 | AU4: =RANK(TAcum[[#This Row],[j45]],TAcum[[#All],[j45]],0) -> 3 | AV4: =RANK(TAcum[[#This Row],[j46]],TAcum[[#All],[j46]],0) -> 3 | AW4: =RANK(TAcum[[#This Row],[j47]],TAcum[[#All],[j47]],0) -> 3 | AX4: =RANK(TAcum[[#This Row],[j48]],TAcum[[#All],[j48]],0) -> 3 | AY4: =RANK(TAcum[[#This Row],[j49]],TAcum[[#All],[j49]],0) -> 3 | AZ4: =RANK(TAcum[[#This Row],[j50]],TAcum[[#All],[j50]],0) -> 3 | BA4: =RANK(TAcum[[#This Row],[j51]],TAcum[[#All],[j51]],0) -> 3 | BB4: =RANK(TAcum[[#This Row],[j52]],TAcum[[#All],[j52]],0) -> 3 | BC4: =RANK(TAcum[[#This Row],[j53]],TAcum[[#All],[j53]],0) -> 3 | BD4: =RANK(TAcum[[#This Row],[j54]],TAcum[[#All],[j54]],0) -> 3 | BE4: =RANK(TAcum[[#This Row],[j55]],TAcum[[#All],[j55]],0) -> 3 | BF4: =RANK(TAcum[[#This Row],[j56]],TAcum[[#All],[j56]],0) -> 3 | BG4: =RANK(TAcum[[#This Row],[j57]],TAcum[[#All],[j57]],0) -> 3 | BH4: =RANK(TAcum[[#This Row],[j58]],TAcum[[#All],[j58]],0) -> 3 | BI4: =RANK(TAcum[[#This Row],[j59]],TAcum[[#All],[j59]],0) -> 3 | BJ4: =RANK(TAcum[[#This Row],[j60]],TAcum[[#All],[j60]],0) -> 3 | BK4: =RANK(TAcum[[#This Row],[j61]],TAcum[[#All],[j61]],0) -> 3 | BL4: =RANK(TAcum[[#This Row],[j62]],TAcum[[#All],[j62]],0) -> 3 | BM4: =RANK(TAcum[[#This Row],[j63]],TAcum[[#All],[j63]],0) -> 3 | BN4: =RANK(TAcum[[#This Row],[j64]],TAcum[[#All],[j64]],0) -> 3 | BO4: =RANK(TAcum[[#This Row],[j65]],TAcum[[#All],[j65]],0) -> 3 | BP4: =RANK(TAcum[[#This Row],[j66]],TAcum[[#All],[j66]],0) -> 3 | BQ4: =RANK(TAcum[[#This Row],[j67]],TAcum[[#All],[j67]],0) -> 3 | BR4: =RANK(TAcum[[#This Row],[j68]],TAcum[[#All],[j68]],0) -> 3 | BS4: =RANK(TAcum[[#This Row],[j69]],TAcum[[#All],[j69]],0) -> 3 | BT4: =RANK(TAcum[[#This Row],[j70]],TAcum[[#All],[j70]],0) -> 3 | BU4: =RANK(TAcum[[#This Row],[j71]],TAcum[[#All],[j71]],0) -> 3 | BV4: =RANK(TAcum[[#This Row],[j72]],TAcum[[#All],[j72]],0) -> 3 | BW4: =RANK(TAcum[[#This Row],[j73]],TAcum[[#All],[j73]],0) -> 3
A5: =TAcum[[#This Row],[Jogador]] -> Fábio Luis Dos Santo Aleluia | B5: =RANK(TAcum[[#This Row],[total]],TAcum[[#All],[total]],0) -> 3 | C5: =RANK(TAcum[[#This Row],[j01]],TAcum[[#All],[j01]],0) -> 1 | D5: =RANK(TAcum[[#This Row],[j02]],TAcum[[#All],[j02]],0) -> 1 | E5: =RANK(TAcum[[#This Row],[j03]],TAcum[[#All],[j03]],0) -> 3 | F5: =RANK(TAcum[[#This Row],[j04]],TAcum[[#All],[j04]],0) -> 38 | G5: =RANK(TAcum[[#This Row],[j05]],TAcum[[#All],[j05]],0) -> 39 | H5: =RANK(TAcum[[#This Row],[j06]],TAcum[[#All],[j06]],0) -> 41 | I5: =RANK(TAcum[[#This Row],[j07]],TAcum[[#All],[j07]],0) -> 49 | J5: =RANK(TAcum[[#This Row],[j08]],TAcum[[#All],[j08]],0) -> 49 | K5: =RANK(TAcum[[#This Row],[j09]],TAcum[[#All],[j09]],0) -> 52 | L5: =RANK(TAcum[[#This Row],[j10]],TAcum[[#All],[j10]],0) -> 56 | M5: =RANK(TAcum[[#This Row],[j11]],TAcum[[#All],[j11]],0) -> 51 | N5: =RANK(TAcum[[#This Row],[j12]],TAcum[[#All],[j12]],0) -> 54 | O5: =RANK(TAcum[[#This Row],[j13]],TAcum[[#All],[j13]],0) -> 33 | P5: =RANK(TAcum[[#This Row],[j14]],TAcum[[#All],[j14]],0) -> 35 | Q5: =RANK(TAcum[[#This Row],[j15]],TAcum[[#All],[j15]],0) -> 36 | R5: =RANK(TAcum[[#This Row],[j16]],TAcum[[#All],[j16]],0) -> 27 | S5: =RANK(TAcum[[#This Row],[j17]],TAcum[[#All],[j17]],0) -> 32 | T5: =RANK(TAcum[[#This Row],[j18]],TAcum[[#All],[j18]],0) -> 37 | U5: =RANK(TAcum[[#This Row],[j19]],TAcum[[#All],[j19]],0) -> 16 | V5: =RANK(TAcum[[#This Row],[j20]],TAcum[[#All],[j20]],0) -> 24 | W5: =RANK(TAcum[[#This Row],[j21]],TAcum[[#All],[j21]],0) -> 5 | X5: =RANK(TAcum[[#This Row],[j22]],TAcum[[#All],[j22]],0) -> 6 | Y5: =RANK(TAcum[[#This Row],[j23]],TAcum[[#All],[j23]],0) -> 6 | Z5: =RANK(TAcum[[#This Row],[j24]],TAcum[[#All],[j24]],0) -> 8 | AA5: =RANK(TAcum[[#This Row],[j25]],TAcum[[#All],[j25]],0) -> 8 | AB5: =RANK(TAcum[[#This Row],[j26]],TAcum[[#All],[j26]],0) -> 3 | AC5: =RANK(TAcum[[#This Row],[j27]],TAcum[[#All],[j27]],0) -> 3 | AD5: =RANK(TAcum[[#This Row],[j28]],TAcum[[#All],[j28]],0) -> 2 | AE5: =RANK(TAcum[[#This Row],[j29]],TAcum[[#All],[j29]],0) -> 3 | AF5: =RANK(TAcum[[#This Row],[j30]],TAcum[[#All],[j30]],0) -> 3 | AG5: =RANK(TAcum[[#This Row],[j31]],TAcum[[#All],[j31]],0) -> 3 | AH5: =RANK(TAcum[[#This Row],[j32]],TAcum[[#All],[j32]],0) -> 3 | AI5: =RANK(TAcum[[#This Row],[j33]],TAcum[[#All],[j33]],0) -> 3 | AJ5: =RANK(TAcum[[#This Row],[j34]],TAcum[[#All],[j34]],0) -> 3 | AK5: =RANK(TAcum[[#This Row],[j35]],TAcum[[#All],[j35]],0) -> 3 | AL5: =RANK(TAcum[[#This Row],[j36]],TAcum[[#All],[j36]],0) -> 3 | AM5: =RANK(TAcum[[#This Row],[j37]],TAcum[[#All],[j37]],0) -> 3 | AN5: =RANK(TAcum[[#This Row],[j38]],TAcum[[#All],[j38]],0) -> 3 | AO5: =RANK(TAcum[[#This Row],[j39]],TAcum[[#All],[j39]],0) -> 3 | AP5: =RANK(TAcum[[#This Row],[j40]],TAcum[[#All],[j40]],0) -> 3 | AQ5: =RANK(TAcum[[#This Row],[j41]],TAcum[[#All],[j41]],0) -> 3 | AR5: =RANK(TAcum[[#This Row],[j42]],TAcum[[#All],[j42]],0) -> 3 | AS5: =RANK(TAcum[[#This Row],[j43]],TAcum[[#All],[j43]],0) -> 3 | AT5: =RANK(TAcum[[#This Row],[j44]],TAcum[[#All],[j44]],0) -> 3 | AU5: =RANK(TAcum[[#This Row],[j45]],TAcum[[#All],[j45]],0) -> 3 | AV5: =RANK(TAcum[[#This Row],[j46]],TAcum[[#All],[j46]],0) -> 3 | AW5: =RANK(TAcum[[#This Row],[j47]],TAcum[[#All],[j47]],0) -> 3 | AX5: =RANK(TAcum[[#This Row],[j48]],TAcum[[#All],[j48]],0) -> 3 | AY5: =RANK(TAcum[[#This Row],[j49]],TAcum[[#All],[j49]],0) -> 3 | AZ5: =RANK(TAcum[[#This Row],[j50]],TAcum[[#All],[j50]],0) -> 3 | BA5: =RANK(TAcum[[#This Row],[j51]],TAcum[[#All],[j51]],0) -> 3 | BB5: =RANK(TAcum[[#This Row],[j52]],TAcum[[#All],[j52]],0) -> 3 | BC5: =RANK(TAcum[[#This Row],[j53]],TAcum[[#All],[j53]],0) -> 3 | BD5: =RANK(TAcum[[#This Row],[j54]],TAcum[[#All],[j54]],0) -> 3 | BE5: =RANK(TAcum[[#This Row],[j55]],TAcum[[#All],[j55]],0) -> 3 | BF5: =RANK(TAcum[[#This Row],[j56]],TAcum[[#All],[j56]],0) -> 3 | BG5: =RANK(TAcum[[#This Row],[j57]],TAcum[[#All],[j57]],0) -> 3 | BH5: =RANK(TAcum[[#This Row],[j58]],TAcum[[#All],[j58]],0) -> 3 | BI5: =RANK(TAcum[[#This Row],[j59]],TAcum[[#All],[j59]],0) -> 3 | BJ5: =RANK(TAcum[[#This Row],[j60]],TAcum[[#All],[j60]],0) -> 3 | BK5: =RANK(TAcum[[#This Row],[j61]],TAcum[[#All],[j61]],0) -> 3 | BL5: =RANK(TAcum[[#This Row],[j62]],TAcum[[#All],[j62]],0) -> 3 | BM5: =RANK(TAcum[[#This Row],[j63]],TAcum[[#All],[j63]],0) -> 3 | BN5: =RANK(TAcum[[#This Row],[j64]],TAcum[[#All],[j64]],0) -> 3 | BO5: =RANK(TAcum[[#This Row],[j65]],TAcum[[#All],[j65]],0) -> 3 | BP5: =RANK(TAcum[[#This Row],[j66]],TAcum[[#All],[j66]],0) -> 3 | BQ5: =RANK(TAcum[[#This Row],[j67]],TAcum[[#All],[j67]],0) -> 3 | BR5: =RANK(TAcum[[#This Row],[j68]],TAcum[[#All],[j68]],0) -> 3 | BS5: =RANK(TAcum[[#This Row],[j69]],TAcum[[#All],[j69]],0) -> 3 | BT5: =RANK(TAcum[[#This Row],[j70]],TAcum[[#All],[j70]],0) -> 3 | BU5: =RANK(TAcum[[#This Row],[j71]],TAcum[[#All],[j71]],0) -> 3 | BV5: =RANK(TAcum[[#This Row],[j72]],TAcum[[#All],[j72]],0) -> 3 | BW5: =RANK(TAcum[[#This Row],[j73]],TAcum[[#All],[j73]],0) -> 3
A6: =TAcum[[#This Row],[Jogador]] -> Gabriel Coni | B6: =RANK(TAcum[[#This Row],[total]],TAcum[[#All],[total]],0) -> 5 | C6: =RANK(TAcum[[#This Row],[j01]],TAcum[[#All],[j01]],0) -> 13 | D6: =RANK(TAcum[[#This Row],[j02]],TAcum[[#All],[j02]],0) -> 14 | E6: =RANK(TAcum[[#This Row],[j03]],TAcum[[#All],[j03]],0) -> 24 | F6: =RANK(TAcum[[#This Row],[j04]],TAcum[[#All],[j04]],0) -> 9 | G6: =RANK(TAcum[[#This Row],[j05]],TAcum[[#All],[j05]],0) -> 9 | H6: =RANK(TAcum[[#This Row],[j06]],TAcum[[#All],[j06]],0) -> 9 | I6: =RANK(TAcum[[#This Row],[j07]],TAcum[[#All],[j07]],0) -> 5 | J6: =RANK(TAcum[[#This Row],[j08]],TAcum[[#All],[j08]],0) -> 4 | K6: =RANK(TAcum[[#This Row],[j09]],TAcum[[#All],[j09]],0) -> 6 | L6: =RANK(TAcum[[#This Row],[j10]],TAcum[[#All],[j10]],0) -> 7 | M6: =RANK(TAcum[[#This Row],[j11]],TAcum[[#All],[j11]],0) -> 6 | N6: =RANK(TAcum[[#This Row],[j12]],TAcum[[#All],[j12]],0) -> 9 | O6: =RANK(TAcum[[#This Row],[j13]],TAcum[[#All],[j13]],0) -> 5 | P6: =RANK(TAcum[[#This Row],[j14]],TAcum[[#All],[j14]],0) -> 1 | Q6: =RANK(TAcum[[#This Row],[j15]],TAcum[[#All],[j15]],0) -> 1 | R6: =RANK(TAcum[[#This Row],[j16]],TAcum[[#All],[j16]],0) -> 1 | S6: =RANK(TAcum[[#This Row],[j17]],TAcum[[#All],[j17]],0) -> 1 | T6: =RANK(TAcum[[#This Row],[j18]],TAcum[[#All],[j18]],0) -> 1 | U6: =RANK(TAcum[[#This Row],[j19]],TAcum[[#All],[j19]],0) -> 2 | V6: =RANK(TAcum[[#This Row],[j20]],TAcum[[#All],[j20]],0) -> 2 | W6: =RANK(TAcum[[#This Row],[j21]],TAcum[[#All],[j21]],0) -> 2 | X6: =RANK(TAcum[[#This Row],[j22]],TAcum[[#All],[j22]],0) -> 1 | Y6: =RANK(TAcum[[#This Row],[j23]],TAcum[[#All],[j23]],0) -> 1 | Z6: =RANK(TAcum[[#This Row],[j24]],TAcum[[#All],[j24]],0) -> 6 | AA6: =RANK(TAcum[[#This Row],[j25]],TAcum[[#All],[j25]],0) -> 6 | AB6: =RANK(TAcum[[#This Row],[j26]],TAcum[[#All],[j26]],0) -> 7 | AC6: =RANK(TAcum[[#This Row],[j27]],TAcum[[#All],[j27]],0) -> 7 | AD6: =RANK(TAcum[[#This Row],[j28]],TAcum[[#All],[j28]],0) -> 5 | AE6: =RANK(TAcum[[#This Row],[j29]],TAcum[[#All],[j29]],0) -> 5 | AF6: =RANK(TAcum[[#This Row],[j30]],TAcum[[#All],[j30]],0) -> 5 | AG6: =RANK(TAcum[[#This Row],[j31]],TAcum[[#All],[j31]],0) -> 5 | AH6: =RANK(TAcum[[#This Row],[j32]],TAcum[[#All],[j32]],0) -> 5 | AI6: =RANK(TAcum[[#This Row],[j33]],TAcum[[#All],[j33]],0) -> 5 | AJ6: =RANK(TAcum[[#This Row],[j34]],TAcum[[#All],[j34]],0) -> 5 | AK6: =RANK(TAcum[[#This Row],[j35]],TAcum[[#All],[j35]],0) -> 5 | AL6: =RANK(TAcum[[#This Row],[j36]],TAcum[[#All],[j36]],0) -> 5 | AM6: =RANK(TAcum[[#This Row],[j37]],TAcum[[#All],[j37]],0) -> 5 | AN6: =RANK(TAcum[[#This Row],[j38]],TAcum[[#All],[j38]],0) -> 5 | AO6: =RANK(TAcum[[#This Row],[j39]],TAcum[[#All],[j39]],0) -> 5 | AP6: =RANK(TAcum[[#This Row],[j40]],TAcum[[#All],[j40]],0) -> 5 | AQ6: =RANK(TAcum[[#This Row],[j41]],TAcum[[#All],[j41]],0) -> 5 | AR6: =RANK(TAcum[[#This Row],[j42]],TAcum[[#All],[j42]],0) -> 5 | AS6: =RANK(TAcum[[#This Row],[j43]],TAcum[[#All],[j43]],0) -> 5 | AT6: =RANK(TAcum[[#This Row],[j44]],TAcum[[#All],[j44]],0) -> 5 | AU6: =RANK(TAcum[[#This Row],[j45]],TAcum[[#All],[j45]],0) -> 5 | AV6: =RANK(TAcum[[#This Row],[j46]],TAcum[[#All],[j46]],0) -> 5 | AW6: =RANK(TAcum[[#This Row],[j47]],TAcum[[#All],[j47]],0) -> 5 | AX6: =RANK(TAcum[[#This Row],[j48]],TAcum[[#All],[j48]],0) -> 5 | AY6: =RANK(TAcum[[#This Row],[j49]],TAcum[[#All],[j49]],0) -> 5 | AZ6: =RANK(TAcum[[#This Row],[j50]],TAcum[[#All],[j50]],0) -> 5 | BA6: =RANK(TAcum[[#This Row],[j51]],TAcum[[#All],[j51]],0) -> 5 | BB6: =RANK(TAcum[[#This Row],[j52]],TAcum[[#All],[j52]],0) -> 5 | BC6: =RANK(TAcum[[#This Row],[j53]],TAcum[[#All],[j53]],0) -> 5 | BD6: =RANK(TAcum[[#This Row],[j54]],TAcum[[#All],[j54]],0) -> 5 | BE6: =RANK(TAcum[[#This Row],[j55]],TAcum[[#All],[j55]],0) -> 5 | BF6: =RANK(TAcum[[#This Row],[j56]],TAcum[[#All],[j56]],0) -> 5 | BG6: =RANK(TAcum[[#This Row],[j57]],TAcum[[#All],[j57]],0) -> 5 | BH6: =RANK(TAcum[[#This Row],[j58]],TAcum[[#All],[j58]],0) -> 5 | BI6: =RANK(TAcum[[#This Row],[j59]],TAcum[[#All],[j59]],0) -> 5 | BJ6: =RANK(TAcum[[#This Row],[j60]],TAcum[[#All],[j60]],0) -> 5 | BK6: =RANK(TAcum[[#This Row],[j61]],TAcum[[#All],[j61]],0) -> 5 | BL6: =RANK(TAcum[[#This Row],[j62]],TAcum[[#All],[j62]],0) -> 5 | BM6: =RANK(TAcum[[#This Row],[j63]],TAcum[[#All],[j63]],0) -> 5 | BN6: =RANK(TAcum[[#This Row],[j64]],TAcum[[#All],[j64]],0) -> 5 | BO6: =RANK(TAcum[[#This Row],[j65]],TAcum[[#All],[j65]],0) -> 5 | BP6: =RANK(TAcum[[#This Row],[j66]],TAcum[[#All],[j66]],0) -> 5 | BQ6: =RANK(TAcum[[#This Row],[j67]],TAcum[[#All],[j67]],0) -> 5 | BR6: =RANK(TAcum[[#This Row],[j68]],TAcum[[#All],[j68]],0) -> 5 | BS6: =RANK(TAcum[[#This Row],[j69]],TAcum[[#All],[j69]],0) -> 5 | BT6: =RANK(TAcum[[#This Row],[j70]],TAcum[[#All],[j70]],0) -> 5 | BU6: =RANK(TAcum[[#This Row],[j71]],TAcum[[#All],[j71]],0) -> 5 | BV6: =RANK(TAcum[[#This Row],[j72]],TAcum[[#All],[j72]],0) -> 5 | BW6: =RANK(TAcum[[#This Row],[j73]],TAcum[[#All],[j73]],0) -> 5
A7: =TAcum[[#This Row],[Jogador]] -> Paulo Machado | B7: =RANK(TAcum[[#This Row],[total]],TAcum[[#All],[total]],0) -> 5 | C7: =RANK(TAcum[[#This Row],[j01]],TAcum[[#All],[j01]],0) -> 62 | D7: =RANK(TAcum[[#This Row],[j02]],TAcum[[#All],[j02]],0) -> 59 | E7: =RANK(TAcum[[#This Row],[j03]],TAcum[[#All],[j03]],0) -> 52 | F7: =RANK(TAcum[[#This Row],[j04]],TAcum[[#All],[j04]],0) -> 27 | G7: =RANK(TAcum[[#This Row],[j05]],TAcum[[#All],[j05]],0) -> 27 | H7: =RANK(TAcum[[#This Row],[j06]],TAcum[[#All],[j06]],0) -> 23 | I7: =RANK(TAcum[[#This Row],[j07]],TAcum[[#All],[j07]],0) -> 16 | J7: =RANK(TAcum[[#This Row],[j08]],TAcum[[#All],[j08]],0) -> 8 | K7: =RANK(TAcum[[#This Row],[j09]],TAcum[[#All],[j09]],0) -> 3 | L7: =RANK(TAcum[[#This Row],[j10]],TAcum[[#All],[j10]],0) -> 4 | M7: =RANK(TAcum[[#This Row],[j11]],TAcum[[#All],[j11]],0) -> 23 | N7: =RANK(TAcum[[#This Row],[j12]],TAcum[[#All],[j12]],0) -> 22 | O7: =RANK(TAcum[[#This Row],[j13]],TAcum[[#All],[j13]],0) -> 46 | P7: =RANK(TAcum[[#This Row],[j14]],TAcum[[#All],[j14]],0) -> 15 | Q7: =RANK(TAcum[[#This Row],[j15]],TAcum[[#All],[j15]],0) -> 16 | R7: =RANK(TAcum[[#This Row],[j16]],TAcum[[#All],[j16]],0) -> 19 | S7: =RANK(TAcum[[#This Row],[j17]],TAcum[[#All],[j17]],0) -> 23 | T7: =RANK(TAcum[[#This Row],[j18]],TAcum[[#All],[j18]],0) -> 22 | U7: =RANK(TAcum[[#This Row],[j19]],TAcum[[#All],[j19]],0) -> 38 | V7: =RANK(TAcum[[#This Row],[j20]],TAcum[[#All],[j20]],0) -> 12 | W7: =RANK(TAcum[[#This Row],[j21]],TAcum[[#All],[j21]],0) -> 10 | X7: =RANK(TAcum[[#This Row],[j22]],TAcum[[#All],[j22]],0) -> 3 | Y7: =RANK(TAcum[[#This Row],[j23]],TAcum[[#All],[j23]],0) -> 4 | Z7: =RANK(TAcum[[#This Row],[j24]],TAcum[[#All],[j24]],0) -> 7 | AA7: =RANK(TAcum[[#This Row],[j25]],TAcum[[#All],[j25]],0) -> 4 | AB7: =RANK(TAcum[[#This Row],[j26]],TAcum[[#All],[j26]],0) -> 6 | AC7: =RANK(TAcum[[#This Row],[j27]],TAcum[[#All],[j27]],0) -> 6 | AD7: =RANK(TAcum[[#This Row],[j28]],TAcum[[#All],[j28]],0) -> 5 | AE7: =RANK(TAcum[[#This Row],[j29]],TAcum[[#All],[j29]],0) -> 5 | AF7: =RANK(TAcum[[#This Row],[j30]],TAcum[[#All],[j30]],0) -> 5 | AG7: =RANK(TAcum[[#This Row],[j31]],TAcum[[#All],[j31]],0) -> 5 | AH7: =RANK(TAcum[[#This Row],[j32]],TAcum[[#All],[j32]],0) -> 5 | AI7: =RANK(TAcum[[#This Row],[j33]],TAcum[[#All],[j33]],0) -> 5 | AJ7: =RANK(TAcum[[#This Row],[j34]],TAcum[[#All],[j34]],0) -> 5 | AK7: =RANK(TAcum[[#This Row],[j35]],TAcum[[#All],[j35]],0) -> 5 | AL7: =RANK(TAcum[[#This Row],[j36]],TAcum[[#All],[j36]],0) -> 5 | AM7: =RANK(TAcum[[#This Row],[j37]],TAcum[[#All],[j37]],0) -> 5 | AN7: =RANK(TAcum[[#This Row],[j38]],TAcum[[#All],[j38]],0) -> 5 | AO7: =RANK(TAcum[[#This Row],[j39]],TAcum[[#All],[j39]],0) -> 5 | AP7: =RANK(TAcum[[#This Row],[j40]],TAcum[[#All],[j40]],0) -> 5 | AQ7: =RANK(TAcum[[#This Row],[j41]],TAcum[[#All],[j41]],0) -> 5 | AR7: =RANK(TAcum[[#This Row],[j42]],TAcum[[#All],[j42]],0) -> 5 | AS7: =RANK(TAcum[[#This Row],[j43]],TAcum[[#All],[j43]],0) -> 5 | AT7: =RANK(TAcum[[#This Row],[j44]],TAcum[[#All],[j44]],0) -> 5 | AU7: =RANK(TAcum[[#This Row],[j45]],TAcum[[#All],[j45]],0) -> 5 | AV7: =RANK(TAcum[[#This Row],[j46]],TAcum[[#All],[j46]],0) -> 5 | AW7: =RANK(TAcum[[#This Row],[j47]],TAcum[[#All],[j47]],0) -> 5 | AX7: =RANK(TAcum[[#This Row],[j48]],TAcum[[#All],[j48]],0) -> 5 | AY7: =RANK(TAcum[[#This Row],[j49]],TAcum[[#All],[j49]],0) -> 5 | AZ7: =RANK(TAcum[[#This Row],[j50]],TAcum[[#All],[j50]],0) -> 5 | BA7: =RANK(TAcum[[#This Row],[j51]],TAcum[[#All],[j51]],0) -> 5 | BB7: =RANK(TAcum[[#This Row],[j52]],TAcum[[#All],[j52]],0) -> 5 | BC7: =RANK(TAcum[[#This Row],[j53]],TAcum[[#All],[j53]],0) -> 5 | BD7: =RANK(TAcum[[#This Row],[j54]],TAcum[[#All],[j54]],0) -> 5 | BE7: =RANK(TAcum[[#This Row],[j55]],TAcum[[#All],[j55]],0) -> 5 | BF7: =RANK(TAcum[[#This Row],[j56]],TAcum[[#All],[j56]],0) -> 5 | BG7: =RANK(TAcum[[#This Row],[j57]],TAcum[[#All],[j57]],0) -> 5 | BH7: =RANK(TAcum[[#This Row],[j58]],TAcum[[#All],[j58]],0) -> 5 | BI7: =RANK(TAcum[[#This Row],[j59]],TAcum[[#All],[j59]],0) -> 5 | BJ7: =RANK(TAcum[[#This Row],[j60]],TAcum[[#All],[j60]],0) -> 5 | BK7: =RANK(TAcum[[#This Row],[j61]],TAcum[[#All],[j61]],0) -> 5 | BL7: =RANK(TAcum[[#This Row],[j62]],TAcum[[#All],[j62]],0) -> 5 | BM7: =RANK(TAcum[[#This Row],[j63]],TAcum[[#All],[j63]],0) -> 5 | BN7: =RANK(TAcum[[#This Row],[j64]],TAcum[[#All],[j64]],0) -> 5 | BO7: =RANK(TAcum[[#This Row],[j65]],TAcum[[#All],[j65]],0) -> 5 | BP7: =RANK(TAcum[[#This Row],[j66]],TAcum[[#All],[j66]],0) -> 5 | BQ7: =RANK(TAcum[[#This Row],[j67]],TAcum[[#All],[j67]],0) -> 5 | BR7: =RANK(TAcum[[#This Row],[j68]],TAcum[[#All],[j68]],0) -> 5 | BS7: =RANK(TAcum[[#This Row],[j69]],TAcum[[#All],[j69]],0) -> 5 | BT7: =RANK(TAcum[[#This Row],[j70]],TAcum[[#All],[j70]],0) -> 5 | BU7: =RANK(TAcum[[#This Row],[j71]],TAcum[[#All],[j71]],0) -> 5 | BV7: =RANK(TAcum[[#This Row],[j72]],TAcum[[#All],[j72]],0) -> 5 | BW7: =RANK(TAcum[[#This Row],[j73]],TAcum[[#All],[j73]],0) -> 5
A8: =TAcum[[#This Row],[Jogador]] -> Ivã das Neves Reis | B8: =RANK(TAcum[[#This Row],[total]],TAcum[[#All],[total]],0) -> 7 | C8: =RANK(TAcum[[#This Row],[j01]],TAcum[[#All],[j01]],0) -> 13 | D8: =RANK(TAcum[[#This Row],[j02]],TAcum[[#All],[j02]],0) -> 14 | E8: =RANK(TAcum[[#This Row],[j03]],TAcum[[#All],[j03]],0) -> 3 | F8: =RANK(TAcum[[#This Row],[j04]],TAcum[[#All],[j04]],0) -> 1 | G8: =RANK(TAcum[[#This Row],[j05]],TAcum[[#All],[j05]],0) -> 1 | H8: =RANK(TAcum[[#This Row],[j06]],TAcum[[#All],[j06]],0) -> 1 | I8: =RANK(TAcum[[#This Row],[j07]],TAcum[[#All],[j07]],0) -> 1 | J8: =RANK(TAcum[[#This Row],[j08]],TAcum[[#All],[j08]],0) -> 1 | K8: =RANK(TAcum[[#This Row],[j09]],TAcum[[#All],[j09]],0) -> 1 | L8: =RANK(TAcum[[#This Row],[j10]],TAcum[[#All],[j10]],0) -> 1 | M8: =RANK(TAcum[[#This Row],[j11]],TAcum[[#All],[j11]],0) -> 1 | N8: =RANK(TAcum[[#This Row],[j12]],TAcum[[#All],[j12]],0) -> 6 | O8: =RANK(TAcum[[#This Row],[j13]],TAcum[[#All],[j13]],0) -> 22 | P8: =RANK(TAcum[[#This Row],[j14]],TAcum[[#All],[j14]],0) -> 23 | Q8: =RANK(TAcum[[#This Row],[j15]],TAcum[[#All],[j15]],0) -> 25 | R8: =RANK(TAcum[[#This Row],[j16]],TAcum[[#All],[j16]],0) -> 30 | S8: =RANK(TAcum[[#This Row],[j17]],TAcum[[#All],[j17]],0) -> 38 | T8: =RANK(TAcum[[#This Row],[j18]],TAcum[[#All],[j18]],0) -> 16 | U8: =RANK(TAcum[[#This Row],[j19]],TAcum[[#All],[j19]],0) -> 7 | V8: =RANK(TAcum[[#This Row],[j20]],TAcum[[#All],[j20]],0) -> 7 | W8: =RANK(TAcum[[#This Row],[j21]],TAcum[[#All],[j21]],0) -> 10 | X8: =RANK(TAcum[[#This Row],[j22]],TAcum[[#All],[j22]],0) -> 3 | Y8: =RANK(TAcum[[#This Row],[j23]],TAcum[[#All],[j23]],0) -> 4 | Z8: =RANK(TAcum[[#This Row],[j24]],TAcum[[#All],[j24]],0) -> 2 | AA8: =RANK(TAcum[[#This Row],[j25]],TAcum[[#All],[j25]],0) -> 7 | AB8: =RANK(TAcum[[#This Row],[j26]],TAcum[[#All],[j26]],0) -> 7 | AC8: =RANK(TAcum[[#This Row],[j27]],TAcum[[#All],[j27]],0) -> 7 | AD8: =RANK(TAcum[[#This Row],[j28]],TAcum[[#All],[j28]],0) -> 8 | AE8: =RANK(TAcum[[#This Row],[j29]],TAcum[[#All],[j29]],0) -> 7 | AF8: =RANK(TAcum[[#This Row],[j30]],TAcum[[#All],[j30]],0) -> 7 | AG8: =RANK(TAcum[[#This Row],[j31]],TAcum[[#All],[j31]],0) -> 7 | AH8: =RANK(TAcum[[#This Row],[j32]],TAcum[[#All],[j32]],0) -> 7 | AI8: =RANK(TAcum[[#This Row],[j33]],TAcum[[#All],[j33]],0) -> 7 | AJ8: =RANK(TAcum[[#This Row],[j34]],TAcum[[#All],[j34]],0) -> 7 | AK8: =RANK(TAcum[[#This Row],[j35]],TAcum[[#All],[j35]],0) -> 7 | AL8: =RANK(TAcum[[#This Row],[j36]],TAcum[[#All],[j36]],0) -> 7 | AM8: =RANK(TAcum[[#This Row],[j37]],TAcum[[#All],[j37]],0) -> 7 | AN8: =RANK(TAcum[[#This Row],[j38]],TAcum[[#All],[j38]],0) -> 7 | AO8: =RANK(TAcum[[#This Row],[j39]],TAcum[[#All],[j39]],0) -> 7 | AP8: =RANK(TAcum[[#This Row],[j40]],TAcum[[#All],[j40]],0) -> 7 | AQ8: =RANK(TAcum[[#This Row],[j41]],TAcum[[#All],[j41]],0) -> 7 | AR8: =RANK(TAcum[[#This Row],[j42]],TAcum[[#All],[j42]],0) -> 7 | AS8: =RANK(TAcum[[#This Row],[j43]],TAcum[[#All],[j43]],0) -> 7 | AT8: =RANK(TAcum[[#This Row],[j44]],TAcum[[#All],[j44]],0) -> 7 | AU8: =RANK(TAcum[[#This Row],[j45]],TAcum[[#All],[j45]],0) -> 7 | AV8: =RANK(TAcum[[#This Row],[j46]],TAcum[[#All],[j46]],0) -> 7 | AW8: =RANK(TAcum[[#This Row],[j47]],TAcum[[#All],[j47]],0) -> 7 | AX8: =RANK(TAcum[[#This Row],[j48]],TAcum[[#All],[j48]],0) -> 7 | AY8: =RANK(TAcum[[#This Row],[j49]],TAcum[[#All],[j49]],0) -> 7 | AZ8: =RANK(TAcum[[#This Row],[j50]],TAcum[[#All],[j50]],0) -> 7 | BA8: =RANK(TAcum[[#This Row],[j51]],TAcum[[#All],[j51]],0) -> 7 | BB8: =RANK(TAcum[[#This Row],[j52]],TAcum[[#All],[j52]],0) -> 7 | BC8: =RANK(TAcum[[#This Row],[j53]],TAcum[[#All],[j53]],0) -> 7 | BD8: =RANK(TAcum[[#This Row],[j54]],TAcum[[#All],[j54]],0) -> 7 | BE8: =RANK(TAcum[[#This Row],[j55]],TAcum[[#All],[j55]],0) -> 7 | BF8: =RANK(TAcum[[#This Row],[j56]],TAcum[[#All],[j56]],0) -> 7 | BG8: =RANK(TAcum[[#This Row],[j57]],TAcum[[#All],[j57]],0) -> 7 | BH8: =RANK(TAcum[[#This Row],[j58]],TAcum[[#All],[j58]],0) -> 7 | BI8: =RANK(TAcum[[#This Row],[j59]],TAcum[[#All],[j59]],0) -> 7 | BJ8: =RANK(TAcum[[#This Row],[j60]],TAcum[[#All],[j60]],0) -> 7 | BK8: =RANK(TAcum[[#This Row],[j61]],TAcum[[#All],[j61]],0) -> 7 | BL8: =RANK(TAcum[[#This Row],[j62]],TAcum[[#All],[j62]],0) -> 7 | BM8: =RANK(TAcum[[#This Row],[j63]],TAcum[[#All],[j63]],0) -> 7 | BN8: =RANK(TAcum[[#This Row],[j64]],TAcum[[#All],[j64]],0) -> 7 | BO8: =RANK(TAcum[[#This Row],[j65]],TAcum[[#All],[j65]],0) -> 7 | BP8: =RANK(TAcum[[#This Row],[j66]],TAcum[[#All],[j66]],0) -> 7 | BQ8: =RANK(TAcum[[#This Row],[j67]],TAcum[[#All],[j67]],0) -> 7 | BR8: =RANK(TAcum[[#This Row],[j68]],TAcum[[#All],[j68]],0) -> 7 | BS8: =RANK(TAcum[[#This Row],[j69]],TAcum[[#All],[j69]],0) -> 7 | BT8: =RANK(TAcum[[#This Row],[j70]],TAcum[[#All],[j70]],0) -> 7 | BU8: =RANK(TAcum[[#This Row],[j71]],TAcum[[#All],[j71]],0) -> 7 | BV8: =RANK(TAcum[[#This Row],[j72]],TAcum[[#All],[j72]],0) -> 7 | BW8: =RANK(TAcum[[#This Row],[j73]],TAcum[[#All],[j73]],0) -> 7
A9: =TAcum[[#This Row],[Jogador]] -> Rafael Vieira Valente | B9: =RANK(TAcum[[#This Row],[total]],TAcum[[#All],[total]],0) -> 8 | C9: =RANK(TAcum[[#This Row],[j01]],TAcum[[#All],[j01]],0) -> 13 | D9: =RANK(TAcum[[#This Row],[j02]],TAcum[[#All],[j02]],0) -> 14 | E9: =RANK(TAcum[[#This Row],[j03]],TAcum[[#All],[j03]],0) -> 24 | F9: =RANK(TAcum[[#This Row],[j04]],TAcum[[#All],[j04]],0) -> 9 | G9: =RANK(TAcum[[#This Row],[j05]],TAcum[[#All],[j05]],0) -> 9 | H9: =RANK(TAcum[[#This Row],[j06]],TAcum[[#All],[j06]],0) -> 23 | I9: =RANK(TAcum[[#This Row],[j07]],TAcum[[#All],[j07]],0) -> 16 | J9: =RANK(TAcum[[#This Row],[j08]],TAcum[[#All],[j08]],0) -> 20 | K9: =RANK(TAcum[[#This Row],[j09]],TAcum[[#All],[j09]],0) -> 21 | L9: =RANK(TAcum[[#This Row],[j10]],TAcum[[#All],[j10]],0) -> 21 | M9: =RANK(TAcum[[#This Row],[j11]],TAcum[[#All],[j11]],0) -> 17 | N9: =RANK(TAcum[[#This Row],[j12]],TAcum[[#All],[j12]],0) -> 7 | O9: =RANK(TAcum[[#This Row],[j13]],TAcum[[#All],[j13]],0) -> 1 | P9: =RANK(TAcum[[#This Row],[j14]],TAcum[[#All],[j14]],0) -> 3 | Q9: =RANK(TAcum[[#This Row],[j15]],TAcum[[#All],[j15]],0) -> 13 | R9: =RANK(TAcum[[#This Row],[j16]],TAcum[[#All],[j16]],0) -> 24 | S9: =RANK(TAcum[[#This Row],[j17]],TAcum[[#All],[j17]],0) -> 28 | T9: =RANK(TAcum[[#This Row],[j18]],TAcum[[#All],[j18]],0) -> 10 | U9: =RANK(TAcum[[#This Row],[j19]],TAcum[[#All],[j19]],0) -> 10 | V9: =RANK(TAcum[[#This Row],[j20]],TAcum[[#All],[j20]],0) -> 15 | W9: =RANK(TAcum[[#This Row],[j21]],TAcum[[#All],[j21]],0) -> 16 | X9: =RANK(TAcum[[#This Row],[j22]],TAcum[[#All],[j22]],0) -> 21 | Y9: =RANK(TAcum[[#This Row],[j23]],TAcum[[#All],[j23]],0) -> 13 | Z9: =RANK(TAcum[[#This Row],[j24]],TAcum[[#All],[j24]],0) -> 28 | AA9: =RANK(TAcum[[#This Row],[j25]],TAcum[[#All],[j25]],0) -> 28 | AB9: =RANK(TAcum[[#This Row],[j26]],TAcum[[#All],[j26]],0) -> 10 | AC9: =RANK(TAcum[[#This Row],[j27]],TAcum[[#All],[j27]],0) -> 10 | AD9: =RANK(TAcum[[#This Row],[j28]],TAcum[[#All],[j28]],0) -> 9 | AE9: =RANK(TAcum[[#This Row],[j29]],TAcum[[#All],[j29]],0) -> 8 | AF9: =RANK(TAcum[[#This Row],[j30]],TAcum[[#All],[j30]],0) -> 8 | AG9: =RANK(TAcum[[#This Row],[j31]],TAcum[[#All],[j31]],0) -> 8 | AH9: =RANK(TAcum[[#This Row],[j32]],TAcum[[#All],[j32]],0) -> 8 | AI9: =RANK(TAcum[[#This Row],[j33]],TAcum[[#All],[j33]],0) -> 8 | AJ9: =RANK(TAcum[[#This Row],[j34]],TAcum[[#All],[j34]],0) -> 8 | AK9: =RANK(TAcum[[#This Row],[j35]],TAcum[[#All],[j35]],0) -> 8 | AL9: =RANK(TAcum[[#This Row],[j36]],TAcum[[#All],[j36]],0) -> 8 | AM9: =RANK(TAcum[[#This Row],[j37]],TAcum[[#All],[j37]],0) -> 8 | AN9: =RANK(TAcum[[#This Row],[j38]],TAcum[[#All],[j38]],0) -> 8 | AO9: =RANK(TAcum[[#This Row],[j39]],TAcum[[#All],[j39]],0) -> 8 | AP9: =RANK(TAcum[[#This Row],[j40]],TAcum[[#All],[j40]],0) -> 8 | AQ9: =RANK(TAcum[[#This Row],[j41]],TAcum[[#All],[j41]],0) -> 8 | AR9: =RANK(TAcum[[#This Row],[j42]],TAcum[[#All],[j42]],0) -> 8 | AS9: =RANK(TAcum[[#This Row],[j43]],TAcum[[#All],[j43]],0) -> 8 | AT9: =RANK(TAcum[[#This Row],[j44]],TAcum[[#All],[j44]],0) -> 8 | AU9: =RANK(TAcum[[#This Row],[j45]],TAcum[[#All],[j45]],0) -> 8 | AV9: =RANK(TAcum[[#This Row],[j46]],TAcum[[#All],[j46]],0) -> 8 | AW9: =RANK(TAcum[[#This Row],[j47]],TAcum[[#All],[j47]],0) -> 8 | AX9: =RANK(TAcum[[#This Row],[j48]],TAcum[[#All],[j48]],0) -> 8 | AY9: =RANK(TAcum[[#This Row],[j49]],TAcum[[#All],[j49]],0) -> 8 | AZ9: =RANK(TAcum[[#This Row],[j50]],TAcum[[#All],[j50]],0) -> 8 | BA9: =RANK(TAcum[[#This Row],[j51]],TAcum[[#All],[j51]],0) -> 8 | BB9: =RANK(TAcum[[#This Row],[j52]],TAcum[[#All],[j52]],0) -> 8 | BC9: =RANK(TAcum[[#This Row],[j53]],TAcum[[#All],[j53]],0) -> 8 | BD9: =RANK(TAcum[[#This Row],[j54]],TAcum[[#All],[j54]],0) -> 8 | BE9: =RANK(TAcum[[#This Row],[j55]],TAcum[[#All],[j55]],0) -> 8 | BF9: =RANK(TAcum[[#This Row],[j56]],TAcum[[#All],[j56]],0) -> 8 | BG9: =RANK(TAcum[[#This Row],[j57]],TAcum[[#All],[j57]],0) -> 8 | BH9: =RANK(TAcum[[#This Row],[j58]],TAcum[[#All],[j58]],0) -> 8 | BI9: =RANK(TAcum[[#This Row],[j59]],TAcum[[#All],[j59]],0) -> 8 | BJ9: =RANK(TAcum[[#This Row],[j60]],TAcum[[#All],[j60]],0) -> 8 | BK9: =RANK(TAcum[[#This Row],[j61]],TAcum[[#All],[j61]],0) -> 8 | BL9: =RANK(TAcum[[#This Row],[j62]],TAcum[[#All],[j62]],0) -> 8 | BM9: =RANK(TAcum[[#This Row],[j63]],TAcum[[#All],[j63]],0) -> 8 | BN9: =RANK(TAcum[[#This Row],[j64]],TAcum[[#All],[j64]],0) -> 8 | BO9: =RANK(TAcum[[#This Row],[j65]],TAcum[[#All],[j65]],0) -> 8 | BP9: =RANK(TAcum[[#This Row],[j66]],TAcum[[#All],[j66]],0) -> 8 | BQ9: =RANK(TAcum[[#This Row],[j67]],TAcum[[#All],[j67]],0) -> 8 | BR9: =RANK(TAcum[[#This Row],[j68]],TAcum[[#All],[j68]],0) -> 8 | BS9: =RANK(TAcum[[#This Row],[j69]],TAcum[[#All],[j69]],0) -> 8 | BT9: =RANK(TAcum[[#This Row],[j70]],TAcum[[#All],[j70]],0) -> 8 | BU9: =RANK(TAcum[[#This Row],[j71]],TAcum[[#All],[j71]],0) -> 8 | BV9: =RANK(TAcum[[#This Row],[j72]],TAcum[[#All],[j72]],0) -> 8 | BW9: =RANK(TAcum[[#This Row],[j73]],TAcum[[#All],[j73]],0) -> 8
A10: =TAcum[[#This Row],[Jogador]] -> Brunner Victor de Almeida | B10: =RANK(TAcum[[#This Row],[total]],TAcum[[#All],[total]],0) -> 9 | C10: =RANK(TAcum[[#This Row],[j01]],TAcum[[#All],[j01]],0) -> 13 | D10: =RANK(TAcum[[#This Row],[j02]],TAcum[[#All],[j02]],0) -> 14 | E10: =RANK(TAcum[[#This Row],[j03]],TAcum[[#All],[j03]],0) -> 3 | F10: =RANK(TAcum[[#This Row],[j04]],TAcum[[#All],[j04]],0) -> 1 | G10: =RANK(TAcum[[#This Row],[j05]],TAcum[[#All],[j05]],0) -> 1 | H10: =RANK(TAcum[[#This Row],[j06]],TAcum[[#All],[j06]],0) -> 1 | I10: =RANK(TAcum[[#This Row],[j07]],TAcum[[#All],[j07]],0) -> 1 | J10: =RANK(TAcum[[#This Row],[j08]],TAcum[[#All],[j08]],0) -> 2 | K10: =RANK(TAcum[[#This Row],[j09]],TAcum[[#All],[j09]],0) -> 2 | L10: =RANK(TAcum[[#This Row],[j10]],TAcum[[#All],[j10]],0) -> 3 | M10: =RANK(TAcum[[#This Row],[j11]],TAcum[[#All],[j11]],0) -> 3 | N10: =RANK(TAcum[[#This Row],[j12]],TAcum[[#All],[j12]],0) -> 1 | O10: =RANK(TAcum[[#This Row],[j13]],TAcum[[#All],[j13]],0) -> 1 | P10: =RANK(TAcum[[#This Row],[j14]],TAcum[[#All],[j14]],0) -> 3 | Q10: =RANK(TAcum[[#This Row],[j15]],TAcum[[#All],[j15]],0) -> 4 | R10: =RANK(TAcum[[#This Row],[j16]],TAcum[[#All],[j16]],0) -> 4 | S10: =RANK(TAcum[[#This Row],[j17]],TAcum[[#All],[j17]],0) -> 3 | T10: =RANK(TAcum[[#This Row],[j18]],TAcum[[#All],[j18]],0) -> 4 | U10: =RANK(TAcum[[#This Row],[j19]],TAcum[[#All],[j19]],0) -> 2 | V10: =RANK(TAcum[[#This Row],[j20]],TAcum[[#All],[j20]],0) -> 2 | W10: =RANK(TAcum[[#This Row],[j21]],TAcum[[#All],[j21]],0) -> 4 | X10: =RANK(TAcum[[#This Row],[j22]],TAcum[[#All],[j22]],0) -> 9 | Y10: =RANK(TAcum[[#This Row],[j23]],TAcum[[#All],[j23]],0) -> 6 | Z10: =RANK(TAcum[[#This Row],[j24]],TAcum[[#All],[j24]],0) -> 4 | AA10: =RANK(TAcum[[#This Row],[j25]],TAcum[[#All],[j25]],0) -> 3 | AB10: =RANK(TAcum[[#This Row],[j26]],TAcum[[#All],[j26]],0) -> 4 | AC10: =RANK(TAcum[[#This Row],[j27]],TAcum[[#All],[j27]],0) -> 4 | AD10: =RANK(TAcum[[#This Row],[j28]],TAcum[[#All],[j28]],0) -> 7 | AE10: =RANK(TAcum[[#This Row],[j29]],TAcum[[#All],[j29]],0) -> 9 | AF10: =RANK(TAcum[[#This Row],[j30]],TAcum[[#All],[j30]],0) -> 9 | AG10: =RANK(TAcum[[#This Row],[j31]],TAcum[[#All],[j31]],0) -> 9 | AH10: =RANK(TAcum[[#This Row],[j32]],TAcum[[#All],[j32]],0) -> 9 | AI10: =RANK(TAcum[[#This Row],[j33]],TAcum[[#All],[j33]],0) -> 9 | AJ10: =RANK(TAcum[[#This Row],[j34]],TAcum[[#All],[j34]],0) -> 9 | AK10: =RANK(TAcum[[#This Row],[j35]],TAcum[[#All],[j35]],0) -> 9 | AL10: =RANK(TAcum[[#This Row],[j36]],TAcum[[#All],[j36]],0) -> 9 | AM10: =RANK(TAcum[[#This Row],[j37]],TAcum[[#All],[j37]],0) -> 9 | AN10: =RANK(TAcum[[#This Row],[j38]],TAcum[[#All],[j38]],0) -> 9 | AO10: =RANK(TAcum[[#This Row],[j39]],TAcum[[#All],[j39]],0) -> 9 | AP10: =RANK(TAcum[[#This Row],[j40]],TAcum[[#All],[j40]],0) -> 9 | AQ10: =RANK(TAcum[[#This Row],[j41]],TAcum[[#All],[j41]],0) -> 9 | AR10: =RANK(TAcum[[#This Row],[j42]],TAcum[[#All],[j42]],0) -> 9 | AS10: =RANK(TAcum[[#This Row],[j43]],TAcum[[#All],[j43]],0) -> 9 | AT10: =RANK(TAcum[[#This Row],[j44]],TAcum[[#All],[j44]],0) -> 9 | AU10: =RANK(TAcum[[#This Row],[j45]],TAcum[[#All],[j45]],0) -> 9 | AV10: =RANK(TAcum[[#This Row],[j46]],TAcum[[#All],[j46]],0) -> 9 | AW10: =RANK(TAcum[[#This Row],[j47]],TAcum[[#All],[j47]],0) -> 9 | AX10: =RANK(TAcum[[#This Row],[j48]],TAcum[[#All],[j48]],0) -> 9 | AY10: =RANK(TAcum[[#This Row],[j49]],TAcum[[#All],[j49]],0) -> 9 | AZ10: =RANK(TAcum[[#This Row],[j50]],TAcum[[#All],[j50]],0) -> 9 | BA10: =RANK(TAcum[[#This Row],[j51]],TAcum[[#All],[j51]],0) -> 9 | BB10: =RANK(TAcum[[#This Row],[j52]],TAcum[[#All],[j52]],0) -> 9 | BC10: =RANK(TAcum[[#This Row],[j53]],TAcum[[#All],[j53]],0) -> 9 | BD10: =RANK(TAcum[[#This Row],[j54]],TAcum[[#All],[j54]],0) -> 9 | BE10: =RANK(TAcum[[#This Row],[j55]],TAcum[[#All],[j55]],0) -> 9 | BF10: =RANK(TAcum[[#This Row],[j56]],TAcum[[#All],[j56]],0) -> 9 | BG10: =RANK(TAcum[[#This Row],[j57]],TAcum[[#All],[j57]],0) -> 9 | BH10: =RANK(TAcum[[#This Row],[j58]],TAcum[[#All],[j58]],0) -> 9 | BI10: =RANK(TAcum[[#This Row],[j59]],TAcum[[#All],[j59]],0) -> 9 | BJ10: =RANK(TAcum[[#This Row],[j60]],TAcum[[#All],[j60]],0) -> 9 | BK10: =RANK(TAcum[[#This Row],[j61]],TAcum[[#All],[j61]],0) -> 9 | BL10: =RANK(TAcum[[#This Row],[j62]],TAcum[[#All],[j62]],0) -> 9 | BM10: =RANK(TAcum[[#This Row],[j63]],TAcum[[#All],[j63]],0) -> 9 | BN10: =RANK(TAcum[[#This Row],[j64]],TAcum[[#All],[j64]],0) -> 9 | BO10: =RANK(TAcum[[#This Row],[j65]],TAcum[[#All],[j65]],0) -> 9 | BP10: =RANK(TAcum[[#This Row],[j66]],TAcum[[#All],[j66]],0) -> 9 | BQ10: =RANK(TAcum[[#This Row],[j67]],TAcum[[#All],[j67]],0) -> 9 | BR10: =RANK(TAcum[[#This Row],[j68]],TAcum[[#All],[j68]],0) -> 9 | BS10: =RANK(TAcum[[#This Row],[j69]],TAcum[[#All],[j69]],0) -> 9 | BT10: =RANK(TAcum[[#This Row],[j70]],TAcum[[#All],[j70]],0) -> 9 | BU10: =RANK(TAcum[[#This Row],[j71]],TAcum[[#All],[j71]],0) -> 9 | BV10: =RANK(TAcum[[#This Row],[j72]],TAcum[[#All],[j72]],0) -> 9 | BW10: =RANK(TAcum[[#This Row],[j73]],TAcum[[#All],[j73]],0) -> 9
